Workbook

Sheet DATA GAPOKTAN 
A1: DATA GABUNGAN KELOMPOK TANI (GAPOKTAN) KECAMATAN POTO TANO TAHUN 2026
A2: No | B2: Nama Desa | C2: Nama Gapoktan | D2: Nama Ketua | E2: Jumlah Anggota (Poktan) | F2: Alamat Sekretariat | G2: Tahun Pembentukan | H2: SK Pengukuhan | I2: Unit Usaha | J2: Status Operasional (Aktif/Tidak Aktif)
A3: 1 | B3: Senayan | C3: Mampis Rungan | D3: Jufriadi | E3: 1 | F3: Dusun Senayan Atas Desa Senayan Kec. Poto Tano | G3: 2007 | H3: - | I3: Simpan_pinjam | J3: Tidak Aktif | L3: =INDEX(desa!A:A,MATCH(B3,desa!B:B,0)) -> 5 | M3: GAPOKTAN | N3: =CONCATENATE("('",L3,";",C3,";",D3,";",E3,";",F3,";",G3,";",J3,";",M3,"'),") -> ('5;Mampis Rungan;Jufriadi;1;Dusun Senayan Atas Desa Senayan Kec. Poto Tano;2007;Tidak Aktif;GAPOKTAN'),
A4: 2 | B4: Mantar | C4: Olat Mantar | D4: Syafaruddin | E4: 0 | F4: Desa Mantar Kec. Poto Tano | G4: 2007 | H4: - | I4: Simpan Pinjam | J4: Tidak Aktif | L4: =INDEX(desa!A:A,MATCH(B4,desa!B:B,0)) -> 3 | M4: GAPOKTAN | N4: =CONCATENATE("('",L4,";",C4,";",D4,";",E4,";",F4,";",G4,";",J4,";",M4,"'),") -> ('3;Olat Mantar;Syafaruddin;0;Desa Mantar Kec. Poto Tano;2007;Tidak Aktif;GAPOKTAN'),
A5: 3 | B5: Kiantar | C5: Kiantar | D5: Alfian | E5: 1 | F5: Dusun Sagena Desa Kiantar Kec. Poto Tano | G5: 2008 | H5: - | I5: Saprodi | J5: Tidak Aktif | L5: =INDEX(desa!A:A,MATCH(B5,desa!B:B,0)) -> 1 | M5: GAPOKTAN | N5: =CONCATENATE("('",L5,";",C5,";",D5,";",E5,";",F5,";",G5,";",J5,";",M5,"'),") -> ('1;Kiantar;Alfian;1;Dusun Sagena Desa Kiantar Kec. Poto Tano;2008;Tidak Aktif;GAPOKTAN'),
A6: 5 | B6: UPT Tambak Sari | C6: Maju Bersama | D6: Ahmad | E6: 10 | F6: Desa UPT Tambak Sari Kec. Poto Tano | G6: 2008 | H6: - | J6: Tidak Aktif | L6: =INDEX(desa!A:A,MATCH(B6,desa!B:B,0)) -> 6 | M6: GAPOKTAN | N6: =CONCATENATE("('",L6,";",C6,";",D6,";",E6,";",F6,";",G6,";",J6,";",M6,"'),") -> ('6;Maju Bersama;Ahmad;10;Desa UPT Tambak Sari Kec. Poto Tano;2008;Tidak Aktif;GAPOKTAN'),
A7: 6 | B7: Kokarlian | C7: Kokar Makmur | D7: Samsul Arifin | E7: 5 | F7: Desa Kokarlian | G7: 2007 | H7: - | I7: Saprodi, simpan pinjam | J7: Tidak Aktif | L7: =INDEX(desa!A:A,MATCH(B7,desa!B:B,0)) -> 2 | M7: GAPOKTAN | N7: =CONCATENATE("('",L7,";",C7,";",D7,";",E7,";",F7,";",G7,";",J7,";",M7,"'),") -> ('2;Kokar Makmur;Samsul Arifin;5;Desa Kokarlian;2007;Tidak Aktif;GAPOKTAN'),
A8: 7 | B8: Tebo | C8: Tutu Ate | D8: A. Hamid Hasim | E8: 2 | F8: Desa Tebo | G8: 2010 | H8: - | I8: Simpan Pinjam | J8: Tidak Aktif | L8: =INDEX(desa!A:A,MATCH(B8,desa!B:B,0)) -> 7 | M8: GAPOKTAN | N8: =CONCATENATE("('",L8,";",C8,";",D8,";",E8,";",F8,";",G8,";",J8,";",M8,"'),") -> ('7;Tutu Ate;A. Hamid Hasim;2;Desa Tebo;2010;Tidak Aktif;GAPOKTAN'),
A9: 8 | B9: Tua Nanga | C9: Bangka Bela | D9: Saparuddin | E9: 1 | F9: Desa Tua Nanga | G9: 2010 | H9: - | I9: Simpan_pinjam | J9: Tidak Aktif | L9: =INDEX(desa!A:A,MATCH(B9,desa!B:B,0)) -> 8 | M9: GAPOKTAN | N9: =CONCATENATE("('",L9,";",C9,";",D9,";",E9,";",F9,";",G9,";",J9,";",M9,"'),") -> ('8;Bangka Bela;Saparuddin;1;Desa Tua Nanga;2010;Tidak Aktif;GAPOKTAN'),
A13: Deskripisi:
A14: - Gapoktan (Gabungan Kelompok Tani) adalah kumpulan beberapa Kelompok Tani yang bergabung dan bekerjasama untuk meningkatkan skala ekonomi dan efisiensi usaha. Kelembagaan Petani ditumbuhkembangkan untuk memenuhi kelayakan usaha skala ekonomi dan efisiensi usaha, sehingga berfungsi sebagai unit usaha penyedia sarana dan prasarana produksi, unit Usahatani/produksi, unit usaha pengolahan, unit usaha pemasaran dan unit usaha keuangan mikro (simpan pinjam). Pada tahap pengembangannya, Gapoktan dapat memberikan pelayanan informasi, teknologi, dan permodalan kepada anggotanya serta menjalin kerjasama melalui kemitraan usaha dengan pihak lain. Penggabungan Poktan ke dalam Gapoktan, diharapkan akan menjadikan Kelembagaan Petani yang kuat dan mandiri serta berdaya saing ((Peraturan Menteri Pertanian Nomor : 67/PERMENTAN/SM.050/12/2016 Tentang Pembinaan Kelembagaan Petani)
A15: - Kecamatan Poto Tano memiliki 7 (tujuh) Kelembagaan Gapoktan, di 7 Desa yang memiliki potensi utama di sektor pertanian, kecuali Desa Poto Tano yang potensi utamanya di sektor perikanan dan kelautan.
A16: - Sumber Data : Aplikasi SIMLUHTAN, Juni 2026; Balai Penyuluhan Pertanian Kecamatan Poto Tano Dinas Pertanian Kabupaten Sumbawa Barat

Sheet DATA POKTAN
A1: DATA KELOMPOK TANI (POKTAN) KECAMATAN POTO TANO TAHUN 2026
A2: No | B2: Nama Desa | C2: Nama Kelompok | D2: Kelas Kelompok | E2: Nama Ketua | F2: Jumlah Anggota | G2: Luas Lahan (M2) | H2: Lokasi / Posisi Koordinat Lahan | I2: Komoditas Utama | J2: Status Oprasional (Aktif/Tidak Aktif) | L2: id Desa | M2: jenis kelompok
A3: 1 | B3: Senayan | C3: Mares Gama | D3: Lanjut | E3: H. Junaidi HS | F3: 17 | G3: 33 | H3: -8.585445, 116.83670700000001 | I3: Jagung | J3: Aktif | L3: =INDEX(desa!A:A,MATCH(B3,desa!B:B,0)) -> 5 | M3: POKTAN | N3: =CONCATENATE("('",L3,";",TRIM(LEFT(C3,FIND(" ",C3)-1)),";",D3,";",E3,";",F3,";",G3,";",H3,";",I3,";",J3,";",M3,"'),") -> ('5;Mares Gama;Lanjut;H. Junaidi HS;17;33;-8.585445, 116.83670700000001;Jagung;Aktif;POKTAN'),
A4: 2 | B4: Senayan | C4: Semangat Baru Tambah Anggota Tambah Bantuan Komoditas yang diusahakan Input Jenis Kelompok Ubah Hapus | D4: Lanjut | E4: Samsun HJ | F4: 29 | G4: 52.7 | H4: -8.591425, 116.84190333333332 | I4: Jagung | J4: Aktif | L4: =INDEX(desa!A:A,MATCH(B4,desa!B:B,0)) -> 5 | M4: POKTAN | N4: =CONCATENATE("('",L4,";",TRIM(LEFT(C4,FIND(" ",C4)-1)),";",D4,";",E4,";",F4,";",G4,";",H4,";",I4,";",J4,";",M4,"'),") -> ('5;Semangat Baru;Lanjut;Samsun HJ;29;52.7;-8.591425, 116.84190333333332;Jagung;Aktif;POKTAN'),
A5: 3 | B5: Senayan | C5: Suka Maju Tambah Anggota Tambah Bantuan Komoditas yang diusahakan Input Jenis Kelompok Ubah Hapus | D5: Pemula | E5: Tamrin | F5: 23 | G5: 39 | H5: -8.584915, 116.83269666666665 | I5: Jagung | J5: Aktif | L5: =INDEX(desa!A:A,MATCH(B5,desa!B:B,0)) -> 5 | M5: POKTAN | N5: =CONCATENATE("('",L5,";",TRIM(LEFT(C5,FIND(" ",C5)-1)),";",D5,";",E5,";",F5,";",G5,";",H5,";",I5,";",J5,";",M5,"'),") -> ('5;Suka Maju;Pemula;Tamrin;23;39;-8.584915, 116.83269666666665;Jagung;Aktif;POKTAN'),
A6: 4 | B6: Senayan | C6: Alam Subur Tambah Anggota Tambah Bantuan Komoditas yang diusahakan Input Jenis Kelompok Ubah Hapus | D6: Pemula | E6: Bahtiyar HMY | F6: 24 | G6: 34 | H6: -8.582983, 116.831105 | I6: Jagung | J6: Aktif | L6: =INDEX(desa!A:A,MATCH(B6,desa!B:B,0)) -> 5 | M6: POKTAN | N6: =CONCATENATE("('",L6,";",TRIM(LEFT(C6,FIND(" ",C6)-1)),";",D6,";",E6,";",F6,";",G6,";",H6,";",I6,";",J6,";",M6,"'),") -> ('5;Alam Subur;Pemula;Bahtiyar HMY;24;34;-8.582983, 116.831105;Jagung;Aktif;POKTAN'),
A7: 5 | B7: Senayan | C7: Cinta Damai Tambah Anggota Tambah Bantuan Komoditas yang diusahakan Input Jenis Kelompok Ubah Hapus | D7: Lanjut | E7: A. Muin | F7: 50 | G7: 60 | H7: -8.60397, 116.84600333333334 | I7: Jagung | J7: Aktif | L7: =INDEX(desa!A:A,MATCH(B7,desa!B:B,0)) -> 5 | M7: POKTAN | N7: =CONCATENATE("('",L7,";",TRIM(LEFT(C7,FIND(" ",C7)-1)),";",D7,";",E7,";",F7,";",G7,";",H7,";",I7,";",J7,";",M7,"'),") -> ('5;Cinta Damai;Lanjut;A. Muin;50;60;-8.60397, 116.84600333333334;Jagung;Aktif;POKTAN'),
A8: 6 | B8: Senayan | C8: Sekar Group Tambah Anggota Tambah Bantuan Komoditas yang diusahakan Input Jenis Kelompok Ubah Hapus | D8: Pemula | E8: Zainudin Tayub | F8: 41 | G8: 50 | H8: -8.57287, 116.847463333333332 | I8: Jagung | J8: Aktif | L8: =INDEX(desa!A:A,MATCH(B8,desa!B:B,0)) -> 5 | M8: POKTAN | N8: =CONCATENATE("('",L8,";",TRIM(LEFT(C8,FIND(" ",C8)-1)),";",D8,";",E8,";",F8,";",G8,";",H8,";",I8,";",J8,";",M8,"'),") -> ('5;Sekar Group;Pemula;Zainudin Tayub;41;50;-8.57287, 116.847463333333332 ;Jagung;Aktif;POKTAN'),
A9: 7 | B9: Senayan | C9: Bukit Indah Tambah Anggota Tambah Bantuan Komoditas yang diusahakan Input Jenis Kelompok Ubah Hapus | D9: Pemula | E9: Hamzah AR | F9: 32 | G9: 11 | H9: -8.62099, 116.85271666666668 | I9: Padi | J9: Aktif | L9: =INDEX(desa!A:A,MATCH(B9,desa!B:B,0)) -> 5 | M9: POKTAN | N9: =CONCATENATE("('",L9,";",TRIM(LEFT(C9,FIND(" ",C9)-1)),";",D9,";",E9,";",F9,";",G9,";",H9,";",I9,";",J9,";",M9,"'),") -> ('5;Bukit Indah;Pemula;Hamzah AR;32;11;-8.62099, 116.85271666666668;Padi;Aktif;POKTAN'),
A10: 8 | B10: Senayan | C10: Masi Sate I Tambah Anggota Tambah Bantuan Komoditas yang diusahakan Input Jenis Kelompok Ubah Hapus | D10: Pemula | E10: H. Makbul | F10: 29 | G10: 10 | H10: -8.6181531, 116.8574288 | I10: Padi | J10: Aktif | L10: =INDEX(desa!A:A,MATCH(B10,desa!B:B,0)) -> 5 | M10: POKTAN | N10: =CONCATENATE("('",L10,";",TRIM(LEFT(C10,FIND(" ",C10)-1)),";",D10,";",E10,";",F10,";",G10,";",H10,";",I10,";",J10,";",M10,"'),") -> ('5;Masi Sate I;Pemula;H. Makbul;29;10;-8.6181531, 116.8574288;Padi;Aktif;POKTAN'),
A11: 9 | B11: Senayan | C11: Masi Sate II Tambah Anggota Tambah Bantuan Komoditas yang diusahakan Input Jenis Kelompok Ubah Hapus | D11: Pemula | E11: Bakhtiyar HM | F11: 32 | G11: 10 | H11: -8.61709, 116.85678333333333 | I11: Padi | J11: Aktif | L11: =INDEX(desa!A:A,MATCH(B11,desa!B:B,0)) -> 5 | M11: POKTAN | N11: =CONCATENATE("('",L11,";",TRIM(LEFT(C11,FIND(" ",C11)-1)),";",D11,";",E11,";",F11,";",G11,";",H11,";",I11,";",J11,";",M11,"'),") -> ('5;Masi Sate II;Pemula;Bakhtiyar HM;32;10;-8.61709, 116.85678333333333;Padi;Aktif;POKTAN'),
A12: 10 | B12: Senayan | C12: Tari Jangi Tambah Anggota Tambah Bantuan Komoditas yang diusahakan Input Jenis Kelompok Ubah Hapus | D12: Lanjut | E12: M. Arifin SAP | F12: 42 | G12: 11 | H12: -8.614894999999999, 116.849345 | I12: Padi | J12: Aktif | L12: =INDEX(desa!A:A,MATCH(B12,desa!B:B,0)) -> 5 | M12: POKTAN | N12: =CONCATENATE("('",L12,";",TRIM(LEFT(C12,FIND(" ",C12)-1)),";",D12,";",E12,";",F12,";",G12,";",H12,";",I12,";",J12,";",M12,"'),") -> ('5;Tari Jangi;Lanjut;M. Arifin SAP;42;11;-8.614894999999999, 116.849345;Padi;Aktif;POKTAN'),
A13: 11 | B13: Senayan | C13: KWT Melati Tambah Anggota Tambah Bantuan | D13: Lanjut | E13: Hj. Mastur | F13: 11 | I13: Pengolahan Hasil Pertanian | J13: Aktif | L13: =INDEX(desa!A:A,MATCH(B13,desa!B:B,0)) -> 5 | M13: POKTAN | N13: =CONCATENATE("('",L13,";",TRIM(LEFT(C13,FIND(" ",C13)-1)),";",D13,";",E13,";",F13,";",G13,";",H13,";",I13,";",J13,";",M13,"'),") -> ('5;KWT Melati;Lanjut;Hj. Mastur;11;;;Pengolahan Hasil Pertanian;Aktif;POKTAN'),
A14: 12 | B14: Senayan | C14: KWT Melati II Tambah Anggota Tambah Bantuan Komoditas yang diusahakan Input Jenis Kelompok Ubah Hapus | D14: Lanjut | E14: Herianti, S.Pd | F14: 11 | I14: Pengolahan Hasil Pertanian | J14: Aktif | L14: =INDEX(desa!A:A,MATCH(B14,desa!B:B,0)) -> 5 | M14: POKTAN | N14: =CONCATENATE("('",L14,";",TRIM(LEFT(C14,FIND(" ",C14)-1)),";",D14,";",E14,";",F14,";",G14,";",H14,";",I14,";",J14,";",M14,"'),") -> ('5;KWT Melati II;Lanjut;Herianti, S.Pd;11;;;Pengolahan Hasil Pertanian;Aktif;POKTAN'),
A15: 13 | B15: Senayan | C15: Cempaka Tambah Anggota Tambah Bantuan Komoditas yang diusahakan Input Jenis Kelompok Ubah Hapus | D15: Lanjut | E15: Sudarli, HS., S.AP | F15: 33 | G15: 40 | H15: -8.588445, 116.83553166666667 | I15: Jagung | J15: Aktif | L15: =INDEX(desa!A:A,MATCH(B15,desa!B:B,0)) -> 5 | M15: POKTAN | N15: =CONCATENATE("('",L15,";",TRIM(LEFT(C15,FIND(" ",C15)-1)),";",D15,";",E15,";",F15,";",G15,";",H15,";",I15,";",J15,";",M15,"'),") -> ('5;Cempaka;Lanjut;Sudarli, HS., S.AP;33;40;-8.588445, 116.83553166666667;Jagung;Aktif;POKTAN'),
A16: 14 | B16: Senayan | C16: Senap semu Tambah Anggota Tambah Bantuan Komoditas yang diusahakan Input Jenis Kelompok Ubah Hapus | D16: Pemula | E16: Indra Kusuma | F16: 13 | I16: Peternakan | J16: Aktif | L16: =INDEX(desa!A:A,MATCH(B16,desa!B:B,0)) -> 5 | M16: POKTAN | N16: =CONCATENATE("('",L16,";",TRIM(LEFT(C16,FIND(" ",C16)-1)),";",D16,";",E16,";",F16,";",G16,";",H16,";",I16,";",J16,";",M16,"'),") -> ('5;Senap semu;Pemula;Indra Kusuma;13;;;Peternakan;Aktif;POKTAN'),
A17: 15 | B17: Senayan | C17: Saling Angkat Tambah Anggota Tambah Bantuan Komoditas yang diusahakan Input Jenis Kelompok Ubah Hapus | D17: Pemula | E17: Nurdin | F17: 7 | I17: Peternakan | J17: Aktif | L17: =INDEX(desa!A:A,MATCH(B17,desa!B:B,0)) -> 5 | M17: POKTAN | N17: =CONCATENATE("('",L17,";",TRIM(LEFT(C17,FIND(" ",C17)-1)),";",D17,";",E17,";",F17,";",G17,";",H17,";",I17,";",J17,";",M17,"'),") -> ('5;Saling Angkat;Pemula;Nurdin;7;;;Peternakan;Aktif;POKTAN'),
A18: 16 | B18: Senayan | C18: Ai Boro Tambah Anggota Tambah Bantuan Komoditas yang diusahakan Input Jenis Kelompok Ubah Hapus | D18: Pemula | E18: A. Muin | F18: 11 | I18: Peternakan | J18: Aktif | L18: =INDEX(desa!A:A,MATCH(B18,desa!B:B,0)) -> 5 | M18: POKTAN | N18: =CONCATENATE("('",L18,";",TRIM(LEFT(C18,FIND(" ",C18)-1)),";",D18,";",E18,";",F18,";",G18,";",H18,";",I18,";",J18,";",M18,"'),") -> ('5;Ai;Pemula;A. Muin;11;;;Peternakan;Aktif;POKTAN'),
A19: 17 | B19: Senayan | C19: Kuber Kolo Tambah Anggota Tambah Bantuan Komoditas yang diusahakan Input Jenis Kelompok Ubah Hapus | D19: Pemula | E19: M. Saleh | F19: 43 | G19: 64 | H19: -8.6239554, 116.8507255 | I19: Jagung | J19: Aktif | L19: =INDEX(desa!A:A,MATCH(B19,desa!B:B,0)) -> 5 | M19: POKTAN | N19: =CONCATENATE("('",L19,";",TRIM(LEFT(C19,FIND(" ",C19)-1)),";",D19,";",E19,";",F19,";",G19,";",H19,";",I19,";",J19,";",M19,"'),") -> ('5;Kuber Kolo;Pemula;M. Saleh;43;64;-8.6239554, 116.8507255;Jagung;Aktif;POKTAN'),
A20: 18 | B20: Senayan | C20: Olat Dara Tambah Anggota Tambah Bantuan Komoditas yang diusahakan Input Jenis Kelompok Ubah Hapus | D20: Pemula | E20: M. Yasin | F20: 23 | G20: 42.3 | H20: -8.581815, 116.84369999999998 | I20: Jagung | J20: Aktif | L20: =INDEX(desa!A:A,MATCH(B20,desa!B:B,0)) -> 5 | M20: POKTAN | N20: =CONCATENATE("('",L20,";",TRIM(LEFT(C20,FIND(" ",C20)-1)),";",D20,";",E20,";",F20,";",G20,";",H20,";",I20,";",J20,";",M20,"'),") -> ('5;Olat Dara;Pemula;M. Yasin;23;42.3;-8.581815, 116.84369999999998;Jagung;Aktif;POKTAN'),
A21: 19 | B21: Senayan | C21: Olat Dara II Tambah Anggota Tambah Bantuan Komoditas yang diusahakan Input Jenis Kelompok Ubah Hapus | D21: Pemula | E21: Moh. Saleh | F21: 17 | G21: 30 | H21: -8.5885075, 116.8404171 | I21: Jagung | J21: Aktif | L21: =INDEX(desa!A:A,MATCH(B21,desa!B:B,0)) -> 5 | M21: POKTAN | N21: =CONCATENATE("('",L21,";",TRIM(LEFT(C21,FIND(" ",C21)-1)),";",D21,";",E21,";",F21,";",G21,";",H21,";",I21,";",J21,";",M21,"'),") -> ('5;Olat Dara II;Pemula;Moh. Saleh;17;30;-8.5885075, 116.8404171;Jagung;Aktif;POKTAN'),
A22: 20 | B22: Senayan | C22: Ai Lawang II Tambah Anggota Tambah Bantuan Komoditas yang diusahakan Input Jenis Kelompok Ubah Hapus | D22: Pemula | E22: Faesal | F22: 24 | G22: 42 | H22: -8.59036, 116.83675833333334 | I22: Jagung | J22: Aktif | L22: =INDEX(desa!A:A,MATCH(B22,desa!B:B,0)) -> 5 | M22: POKTAN | N22: =CONCATENATE("('",L22,";",TRIM(LEFT(C22,FIND(" ",C22)-1)),";",D22,";",E22,";",F22,";",G22,";",H22,";",I22,";",J22,";",M22,"'),") -> ('5;Ai Lawang II;Pemula;Faesal;24;42;-8.59036, 116.83675833333334;Jagung;Aktif;POKTAN'),
A23: 21 | B23: Senayan | C23: Ai Olat Tambah Anggota Tambah Bantuan Komoditas yang diusahakan Input Jenis Kelompok Ubah Hapus | D23: Pemula | E23: H. Mursidi | F23: 38 | G23: 11 | H23: -8.619568333333332, 116.84483 | I23: Padi | J23: Aktif | L23: =INDEX(desa!A:A,MATCH(B23,desa!B:B,0)) -> 5 | M23: POKTAN | N23: =CONCATENATE("('",L23,";",TRIM(LEFT(C23,FIND(" ",C23)-1)),";",D23,";",E23,";",F23,";",G23,";",H23,";",I23,";",J23,";",M23,"'),") -> ('5;Ai Olat;Pemula;H. Mursidi;38;11;-8.619568333333332, 116.84483;Padi;Aktif;POKTAN'),
A24: 22 | B24: Senayan | C24: Bukit Indah II Tambah Anggota Tambah Bantuan Komoditas yang diusahakan Input Jenis Kelompok Ubah Hapus | D24: Pemula | E24: Burhanuddin | F24: 28 | G24: 11.41 | H24: -8.621035000000001, 116.84726666666666 | I24: Padi | J24: Aktif | L24: =INDEX(desa!A:A,MATCH(B24,desa!B:B,0)) -> 5 | M24: POKTAN | N24: =CONCATENATE("('",L24,";",TRIM(LEFT(C24,FIND(" ",C24)-1)),";",D24,";",E24,";",F24,";",G24,";",H24,";",I24,";",J24,";",M24,"'),") -> ('5;Bukit Indah II;Pemula;Burhanuddin;28;11.41;-8.621035000000001, 116.84726666666666;Padi;Aktif;POKTAN'),
A25: 23 | B25: Senayan | C25: Lemak Jati Tambah Anggota Tambah Bantuan Komoditas yang diusahakan Input Jenis Kelompok Ubah Hapus | D25: Lanjut | E25: Muhammad | F25: 35 | G25: 47 | H25: -8.6150733, 116.8525662 | I25: Jagung | J25: Aktif | L25: =INDEX(desa!A:A,MATCH(B25,desa!B:B,0)) -> 5 | M25: POKTAN | N25: =CONCATENATE("('",L25,";",TRIM(LEFT(C25,FIND(" ",C25)-1)),";",D25,";",E25,";",F25,";",G25,";",H25,";",I25,";",J25,";",M25,"'),") -> ('5;Lemak Jati;Lanjut;Muhammad;35;47;-8.6150733, 116.8525662;Jagung;Aktif;POKTAN'),
A26: 24 | B26: Senayan | C26: Lawang Desa Tambah Anggota Tambah Bantuan Komoditas yang diusahakan Input Jenis Kelompok Ubah Hapus | D26: Pemula | E26: Muhammad Arifin | F26: 9 | I26: Peternakan | J26: Tidak Aktif | L26: =INDEX(desa!A:A,MATCH(B26,desa!B:B,0)) -> 5 | M26: POKTAN | N26: =CONCATENATE("('",L26,";",TRIM(LEFT(C26,FIND(" ",C26)-1)),";",D26,";",E26,";",F26,";",G26,";",H26,";",I26,";",J26,";",M26,"'),") -> ('5;Lawang Desa;Pemula;Muhammad Arifin;9;;;Peternakan;Tidak Aktif;POKTAN'),
A27: 25 | B27: Senayan | C27: Kuang Rea Tambah Anggota Tambah Bantuan Komoditas yang diusahakan Input Jenis Kelompok Ubah Hapus | D27: Pemula | E27: Kasem | F27: 25 | G27: 32 | H27: -8.57735, 116.82529833333335 | I27: Jagung | J27: Aktif | L27: =INDEX(desa!A:A,MATCH(B27,desa!B:B,0)) -> 5 | M27: POKTAN | N27: =CONCATENATE("('",L27,";",TRIM(LEFT(C27,FIND(" ",C27)-1)),";",D27,";",E27,";",F27,";",G27,";",H27,";",I27,";",J27,";",M27,"'),") -> ('5;Kuang Rea;Pemula;Kasem;25;32;-8.57735, 116.82529833333335;Jagung;Aktif;POKTAN'),
A28: 26 | B28: Senayan | C28: Sumer Loka Tambah Anggota Tambah Bantuan Komoditas yang diusahakan Input Jenis Kelompok Ubah Hapus | D28: Pemula | E28: Sopian Hadi | F28: 38 | G28: 10 | H28: -8.616885, 116.85311833333331 | I28: Padi | J28: Aktif | L28: =INDEX(desa!A:A,MATCH(B28,desa!B:B,0)) -> 5 | M28: POKTAN | N28: =CONCATENATE("('",L28,";",TRIM(LEFT(C28,FIND(" ",C28)-1)),";",D28,";",E28,";",F28,";",G28,";",H28,";",I28,";",J28,";",M28,"'),") -> ('5;Sumer Loka;Pemula;Sopian Hadi;38;10;-8.616885, 116.85311833333331;Padi;Aktif;POKTAN'),
A29: 27 | B29: Senayan | C29: Unter pasi Tambah Anggota Tambah Bantuan Komoditas yang diusahakan Input Jenis Kelompok Ubah Hapus | D29: Pemula | E29: Zaeddun | F29: 23 | G29: 48 | H29: -8.580112, 116.8190623 | I29: Jagung | J29: Aktif | L29: =INDEX(desa!A:A,MATCH(B29,desa!B:B,0)) -> 5 | M29: POKTAN | N29: =CONCATENATE("('",L29,";",TRIM(LEFT(C29,FIND(" ",C29)-1)),";",D29,";",E29,";",F29,";",G29,";",H29,";",I29,";",J29,";",M29,"'),") -> ('5;Unter pasi;Pemula;Zaeddun;23;48;-8.580112, 116.8190623;Jagung;Aktif;POKTAN'),
A30: 28 | B30: Senayan | C30: Ai Rawa Tambah Anggota Tambah Bantuan Komoditas yang diusahakan Input Jenis Kelompok Ubah Hapus | D30: Pemula | E30: Supardi | F30: 35 | G30: 54 | H30: -8.595295, 116.838395 | I30: Jagung | J30: Aktif | L30: =INDEX(desa!A:A,MATCH(B30,desa!B:B,0)) -> 5 | M30: POKTAN | N30: =CONCATENATE("('",L30,";",TRIM(LEFT(C30,FIND(" ",C30)-1)),";",D30,";",E30,";",F30,";",G30,";",H30,";",I30,";",J30,";",M30,"'),") -> ('5;Ai Rawa;Pemula;Supardi;35;54;-8.595295, 116.838395;Jagung;Aktif;POKTAN'),
A31: 29 | B31: Senayan | C31: Sate Maju Tambah Anggota Tambah Bantuan Komoditas yang diusahakan Input Jenis Kelompok Ubah Hapus | D31: Pemula | E31: Hadi Sucipto | F31: 33 | G31: 10 | H31: -8.6169516666666667, 116.852855 | I31: Padi | J31: Aktif | L31: =INDEX(desa!A:A,MATCH(B31,desa!B:B,0)) -> 5 | M31: POKTAN | N31: =CONCATENATE("('",L31,";",TRIM(LEFT(C31,FIND(" ",C31)-1)),";",D31,";",E31,";",F31,";",G31,";",H31,";",I31,";",J31,";",M31,"'),") -> ('5;Sate Maju;Pemula;Hadi Sucipto;33;10;-8.6169516666666667, 116.852855;Padi;Aktif;POKTAN'),
A32: 30 | B32: Senayan | C32: Tengkal Telutu Tambah Anggota Tambah Bantuan Komoditas yang diusahakan Input Jenis Kelompok Ubah Hapus | D32: Pemula | E32: Burhanuddin | F32: 9 | I32: Peternakan | J32: Tidak Aktif | L32: =INDEX(desa!A:A,MATCH(B32,desa!B:B,0)) -> 5 | M32: POKTAN | N32: =CONCATENATE("('",L32,";",TRIM(LEFT(C32,FIND(" ",C32)-1)),";",D32,";",E32,";",F32,";",G32,";",H32,";",I32,";",J32,";",M32,"'),") -> ('5;Tengkal Telutu;Pemula;Burhanuddin;9;;;Peternakan;Tidak Aktif;POKTAN'),
A33: 31 | B33: Senayan | C33: Alam Subur II Tambah Anggota Tambah Bantuan Komoditas yang diusahakan Input Jenis Kelompok Ubah Hapus | D33: Pemula | E33: Syarifuddin | F33: 34 | G33: 45 | H33: -8.61541, 116.84525166666666 | I33: Jagung | J33: Aktif | L33: =INDEX(desa!A:A,MATCH(B33,desa!B:B,0)) -> 5 | M33: POKTAN | N33: =CONCATENATE("('",L33,";",TRIM(LEFT(C33,FIND(" ",C33)-1)),";",D33,";",E33,";",F33,";",G33,";",H33,";",I33,";",J33,";",M33,"'),") -> ('5;Alam Subur II;Pemula;Syarifuddin;34;45;-8.61541, 116.84525166666666;Jagung;Aktif;POKTAN'),
A34: 32 | B34: Senayan | C34: Harapan Suci Tambah Anggota Tambah Bantuan Komoditas yang diusahakan Input Jenis Kelompok Ubah Hapus | D34: Pemula | E34: Syamsul Lutfi | F34: 0 | J34: Tidak Aktif | L34: =INDEX(desa!A:A,MATCH(B34,desa!B:B,0)) -> 5 | M34: POKTAN | N34: =CONCATENATE("('",L34,";",TRIM(LEFT(C34,FIND(" ",C34)-1)),";",D34,";",E34,";",F34,";",G34,";",H34,";",I34,";",J34,";",M34,"'),") -> ('5;Harapan Suci;Pemula;Syamsul Lutfi;0;;;;Tidak Aktif;POKTAN'),
A35: 33 | B35: Senayan | C35: Usaha Baru Tambah Anggota Tambah Bantuan Komoditas yang diusahakan Input Jenis Kelompok Ubah Hapus | D35: Pemula | E35: Fatri Murti | F35: 4 | I35: Peternakan | J35: Tidak Aktif | L35: =INDEX(desa!A:A,MATCH(B35,desa!B:B,0)) -> 5 | M35: POKTAN | N35: =CONCATENATE("('",L35,";",TRIM(LEFT(C35,FIND(" ",C35)-1)),";",D35,";",E35,";",F35,";",G35,";",H35,";",I35,";",J35,";",M35,"'),") -> ('5;Usaha Baru;Pemula;Fatri Murti;4;;;Peternakan;Tidak Aktif;POKTAN'),
A36: 34 | B36: Senayan | C36: Ai lawang Tambah Anggota Tambah Bantuan | D36: Pemula | E36: Kaharuddin | F36: 22 | G36: 45 | H36: -8.590275, 116.83659333333331 | I36: Jagung | J36: Aktif | L36: =INDEX(desa!A:A,MATCH(B36,desa!B:B,0)) -> 5 | M36: POKTAN | N36: =CONCATENATE("('",L36,";",TRIM(LEFT(C36,FIND(" ",C36)-1)),";",D36,";",E36,";",F36,";",G36,";",H36,";",I36,";",J36,";",M36,"'),") -> ('5;Ai lawang;Pemula;Kaharuddin;22;45;-8.590275, 116.83659333333331;Jagung;Aktif;POKTAN'),
A37: 35 | B37: Senayan | C37: Satutu Niat Tambah Anggota Tambah Bantuan Komoditas yang diusahakan Input Jenis Kelompok Ubah Hapus | D37: Pemula | E37: A. Wahab | F37: 4 | I37: Peternkan | J37: Tidak Aktif | L37: =INDEX(desa!A:A,MATCH(B37,desa!B:B,0)) -> 5 | M37: POKTAN | N37: =CONCATENATE("('",L37,";",TRIM(LEFT(C37,FIND(" ",C37)-1)),";",D37,";",E37,";",F37,";",G37,";",H37,";",I37,";",J37,";",M37,"'),") -> ('5;Satutu Niat;Pemula;A. Wahab;4;;;Peternkan;Tidak Aktif;POKTAN'),
A38: 36 | B38: Senayan | C38: Ai Jorok Tambah Anggota Tambah Bantuan Komoditas yang diusahakan Input Jenis Kelompok Ubah Hapus | D38: Pemula | E38: Bambang Hermanto | F38: 43 | G38: 45 | H38: -8.59509, 116.84141666666667 | I38: Jagung | J38: Aktif | L38: =INDEX(desa!A:A,MATCH(B38,desa!B:B,0)) -> 5 | M38: POKTAN | N38: =CONCATENATE("('",L38,";",TRIM(LEFT(C38,FIND(" ",C38)-1)),";",D38,";",E38,";",F38,";",G38,";",H38,";",I38,";",J38,";",M38,"'),") -> ('5;Ai Jorok;Pemula;Bambang Hermanto;43;45;-8.59509, 116.84141666666667;Jagung;Aktif;POKTAN'),
A39: 37 | B39: Senayan | C39: Ai Gali | D39: Pemula | E39: Ibrahim | F39: 8 | I39: Peternkaan | J39: Tidak Aktif | L39: =INDEX(desa!A:A,MATCH(B39,desa!B:B,0)) -> 5 | M39: POKTAN | N39: =CONCATENATE("('",L39,";",TRIM(LEFT(C39,FIND(" ",C39)-1)),";",D39,";",E39,";",F39,";",G39,";",H39,";",I39,";",J39,";",M39,"'),") -> ('5;Ai Gali;Pemula;Ibrahim;8;;;Peternkaan;Tidak Aktif;POKTAN'),
A40: 38 | B40: Senayan | C40: Unter Pasi II | D40: Pemula | E40: Mandru | F40: 11 | G40: 20 | H40: -8.5831, 116.831105 | I40: Jagung | J40: Aktif | L40: =INDEX(desa!A:A,MATCH(B40,desa!B:B,0)) -> 5 | M40: POKTAN | N40: =CONCATENATE("('",L40,";",TRIM(LEFT(C40,FIND(" ",C40)-1)),";",D40,";",E40,";",F40,";",G40,";",H40,";",I40,";",J40,";",M40,"'),") -> ('5;Unter Pasi II;Pemula;Mandru;11;20;-8.5831, 116.831105;Jagung;Aktif;POKTAN'),
...

Sheet desa
A1: 1 | B1: Kiantar | C1: 6
A2: 2 | B2: Kokarlian | C2: 6
A3: 3 | B3: Mantar | C3: 6
A4: 4 | B4: Poto Tano | C4: 6
A5: 5 | B5: Senayan | C5: 6
A6: 6 | B6: Tambak Sari | C6: 6
A7: 7 | B7: Tebo | C7: 6
A8: 8 | B8: Tuananga | C8: 6
A9: 8 | B9: Tua nanga | C9: 6
A10: 6 | B10: upt Tambak Sari | C10: 6
