Workbook

Sheet DATA KELEMBAGAAN PERIKANAN
A1: DATA KELEMBAGAAN PERIKANAN KECAMATAN POTO TANO
A3: No. | B3: Desa | C3: Nama Kelompok | D3: Kelas Kelompok | E3: Ketua Kelompok | F3: Jumlah Anggota | G3: Posisi Koordinat Kelompok | H3: Jenis Usaha | I3: Komoditas | J3: Wadah | K3: Teknologi | L3: Luas Lahan (M2) | M3: Status Operasional (Aktif/Tidak Aktif)
A4: 1 | B4: Senayan | C4: KUB Poto Gili | D4: Madya | E4: Syarifuddin Arirs | F4: 15 | H4: Penangkapan | I4: Ikan Laut | M4: Aktif | O4: =INDEX(desa!A:A,MATCH(B4,desa!B:B,0)) -> 5 | P4: PERIKANAN | Q4: =CONCATENATE("('",O4,";",C4,";",D4,";",E4,";",F4,";",G4,";",I4,";",M4,";",P4,"'),") -> ('5;KUB Poto Gili;Madya;Syarifuddin Arirs;15;;Ikan Laut;Aktif;PERIKANAN'),
A5: 2 | B5: Senayan | C5: Poklahsar Sepakek Barokah | D5: Pemula | E5: Fatmawati | F5: 10 | H5: Pengolahan | I5: Ikan Laut | M5: Aktif | O5: =INDEX(desa!A:A,MATCH(B5,desa!B:B,0)) -> 5 | P5: PERIKANAN | Q5: =CONCATENATE("('",O5,";",C5,";",D5,";",E5,";",F5,";",G5,";",I5,";",M5,";",P5,"'),") -> ('5;Poklahsar Sepakek Barokah;Pemula;Fatmawati;10;;Ikan Laut;Aktif;PERIKANAN'),
A6: 3 | B6: Senayan | C6: Jorok Aer | D6: Pemula | E6: M. Zain Lubis | F6: 7 | G6: -8.618196, 116.857232 | H6: Pembesaran | I6: Nila | J6: kolam tanah | L6: 810 | M6: Aktif | O6: =INDEX(desa!A:A,MATCH(B6,desa!B:B,0)) -> 5 | P6: PERIKANAN | Q6: =CONCATENATE("('",O6,";",C6,";",D6,";",E6,";",F6,";",G6,";",I6,";",M6,";",P6,"'),") -> ('5;Jorok Aer;Pemula;M. Zain Lubis;7;-8.618196, 116.857232;Nila;Aktif;PERIKANAN'),
A7: 4 | B7: Kiantar | C7: KUB Pendi Jangi | D7: Madya | E7: Mustaram | F7: 10 | G7: -8.592626, 116.797773 | H7: Penangkapan | I7: Ikan Laut | M7: Aktif | O7: =INDEX(desa!A:A,MATCH(B7,desa!B:B,0)) -> 1 | P7: PERIKANAN | Q7: =CONCATENATE("('",O7,";",C7,";",D7,";",E7,";",F7,";",G7,";",I7,";",M7,";",P7,"'),") -> ('1;KUB Pendi Jangi;Madya;Mustaram;10;-8.592626, 116.797773;Ikan Laut;Aktif;PERIKANAN'),
A8: 5 | B8: Kiantar | C8: KUB Tari Pemendi | D8: Madya | E8: Abu Bakar M | F8: 10 | G8: - | H8: Penangkapan | I8: Ikan Laut | M8: Aktif | O8: =INDEX(desa!A:A,MATCH(B8,desa!B:B,0)) -> 1 | P8: PERIKANAN | Q8: =CONCATENATE("('",O8,";",C8,";",D8,";",E8,";",F8,";",G8,";",I8,";",M8,";",P8,"'),") -> ('1;KUB Tari Pemendi;Madya;Abu Bakar M;10;-;Ikan Laut;Aktif;PERIKANAN'),
A9: 6 | B9: Kiantar | C9: KUB Balong Niat | D9: Pemula | E9: Hasbullah | F9: 10 | H9: Penangkapan | I9: Ikan Laut | M9: Aktif | O9: =INDEX(desa!A:A,MATCH(B9,desa!B:B,0)) -> 1 | P9: PERIKANAN | Q9: =CONCATENATE("('",O9,";",C9,";",D9,";",E9,";",F9,";",G9,";",I9,";",M9,";",P9,"'),") -> ('1;KUB Balong Niat;Pemula;Hasbullah;10;;Ikan Laut;Aktif;PERIKANAN'),
A10: 7 | B10: Kiantar | C10: KUB Saling Pariri | D10: Pemula | E10: Burhanuddin | F10: 10 | H10: Penangkapan | I10: Ikan Laut | M10: Aktif | O10: =INDEX(desa!A:A,MATCH(B10,desa!B:B,0)) -> 1 | P10: PERIKANAN | Q10: =CONCATENATE("('",O10,";",C10,";",D10,";",E10,";",F10,";",G10,";",I10,";",M10,";",P10,"'),") -> ('1;KUB Saling Pariri;Pemula;Burhanuddin;10;;Ikan Laut;Aktif;PERIKANAN'),
A11: 8 | B11: Kiantar | C11: Pokdakan Sagena Bahari | D11: Madya | E11: Syarifuddin P | F11: 10 | G11: -8.580129, 116.816388 | H11: Pembesaran | I11: Rumput Laut | K11: Long Line | L11: 5000 | M11: Aktif | O11: =INDEX(desa!A:A,MATCH(B11,desa!B:B,0)) -> 1 | P11: PERIKANAN | Q11: =CONCATENATE("('",O11,";",C11,";",D11,";",E11,";",F11,";",G11,";",I11,";",M11,";",P11,"'),") -> ('1;Pokdakan Sagena Bahari;Madya;Syarifuddin P;10;-8.580129, 116.816388;Rumput Laut;Aktif;PERIKANAN'),
A12: 9 | B12: Kiantar | C12: Gapokkan Sagena Sejahtera | D12: Pemula | E12: Alfian | F12: 9 | G12: -8.580675, 116.813514 | H12: Pembesaran | I12: Rumput Laut, Kerapu, Bawal | K12: Long Line, KJA | L12: 5000 | M12: Aktif | O12: =INDEX(desa!A:A,MATCH(B12,desa!B:B,0)) -> 1 | P12: PERIKANAN | Q12: =CONCATENATE("('",O12,";",C12,";",D12,";",E12,";",F12,";",G12,";",I12,";",M12,";",P12,"'),") -> ('1;Gapokkan Sagena Sejahtera;Pemula;Alfian;9;-8.580675, 116.813514;Rumput Laut, Kerapu, Bawal;Aktif;PERIKANAN'),
A13: 10 | B13: Kiantar | C13: Pokdakan Pendi Jangi | D13: Pemula | E13: Basaruddin | F13: 10 | G13: -8.580901, 116.813304 | H13: Pembesaran | I13: Rumput Laut, Bawal, Kerapu | K13: Long Line, KJA | L13: 5000 | M13: Aktif | O13: =INDEX(desa!A:A,MATCH(B13,desa!B:B,0)) -> 1 | P13: PERIKANAN | Q13: =CONCATENATE("('",O13,";",C13,";",D13,";",E13,";",F13,";",G13,";",I13,";",M13,";",P13,"'),") -> ('1;Pokdakan Pendi Jangi;Pemula;Basaruddin;10;-8.580901, 116.813304;Rumput Laut, Bawal, Kerapu;Aktif;PERIKANAN'),
A14: 11 | B14: Kiantar | C14: Poklahsar Karya Makmur | D14: Pemula | E14: Ninik Lestari | F14: 10 | G14: - | H14: Pengolahan | I14: Ikan | K14: - | L14: - | M14: Aktif | O14: =INDEX(desa!A:A,MATCH(B14,desa!B:B,0)) -> 1 | P14: PERIKANAN | Q14: =CONCATENATE("('",O14,";",C14,";",D14,";",E14,";",F14,";",G14,";",I14,";",M14,";",P14,"'),") -> ('1;Poklahsar Karya Makmur;Pemula;Ninik Lestari;10;-;Ikan;Aktif;PERIKANAN'),
A15: 12 | B15: Kiantar | C15: Koperasi Serba Usaha Sagena Mandiri Sejahtera | D15: Pemula | E15: Alfian | F15: 20 | G15: - | H15: Pemasaran Hasil Laut | I15: Rumput laut dan ikan | K15: - | L15: - | M15: Aktif | O15: =INDEX(desa!A:A,MATCH(B15,desa!B:B,0)) -> 1 | P15: PERIKANAN | Q15: =CONCATENATE("('",O15,";",C15,";",D15,";",E15,";",F15,";",G15,";",I15,";",M15,";",P15,"'),") -> ('1;Koperasi Serba Usaha Sagena Mandiri Sejahtera;Pemula;Alfian;20;-;Rumput laut dan ikan;Aktif;PERIKANAN'),
A16: 13 | B16: Kiantar | C16: Sinar Bahari | D16: Pemula | E16: Saripuddin | F16: 10 | G16: -8.581327, 116.832145 | H16: Penangkapan | I16: Ikan laut | M16: Aktif | O16: =INDEX(desa!A:A,MATCH(B16,desa!B:B,0)) -> 1 | P16: PERIKANAN | Q16: =CONCATENATE("('",O16,";",C16,";",D16,";",E16,";",F16,";",G16,";",I16,";",M16,";",P16,"'),") -> ('1;Sinar Bahari;Pemula;Saripuddin;10;-8.581327, 116.832145;Ikan laut;Aktif;PERIKANAN'),
A17: 14 | B17: Poto Tano | C17: KUB. Usaha Mandiri | D17: Madya | E17: Margauddin | F17: 10 | G17: -8.528424, 116.832260 | H17: Penangkapan | I17: Ikan laut | K17: - | L17: - | M17: Aktif | O17: =INDEX(desa!A:A,MATCH(B17,desa!B:B,0)) -> 4 | P17: PERIKANAN | Q17: =CONCATENATE("('",O17,";",C17,";",D17,";",E17,";",F17,";",G17,";",I17,";",M17,";",P17,"'),") -> ('4;KUB. Usaha Mandiri;Madya;Margauddin;10;-8.528424, 116.832260;Ikan laut;Aktif;PERIKANAN'),
A18: 15 | B18: Poto Tano | C18: KUB Kakap Merah | D18: Pemula | E18: Najamuddin | F18: 10 | G18: -8. 530699, 116. 832078 | H18: Penangkapan | I18: Ikan laut | M18: Aktif | O18: =INDEX(desa!A:A,MATCH(B18,desa!B:B,0)) -> 4 | P18: PERIKANAN | Q18: =CONCATENATE("('",O18,";",C18,";",D18,";",E18,";",F18,";",G18,";",I18,";",M18,";",P18,"'),") -> ('4;KUB Kakap Merah;Pemula;Najamuddin;10;-8. 530699, 116. 832078;Ikan laut;Aktif;PERIKANAN'),
A19: 16 | B19: Poto Tano | C19: KUB Kuda Laut | D19: Pemula | E19: Kamaruddin B | F19: 10 | G19: -8. 530619, 116. 833139 | H19: Penangkapan | I19: Ikan laut | M19: Aktif | O19: =INDEX(desa!A:A,MATCH(B19,desa!B:B,0)) -> 4 | P19: PERIKANAN | Q19: =CONCATENATE("('",O19,";",C19,";",D19,";",E19,";",F19,";",G19,";",I19,";",M19,";",P19,"'),") -> ('4;KUB Kuda Laut;Pemula;Kamaruddin B;10;-8. 530619, 116. 833139;Ikan laut;Aktif;PERIKANAN'),
A20: 17 | B20: Poto Tano | C20: KUB. Baci Lestari | D20: Pemula | E20: Madahu | F20: 10 | G20: -8. 528489, 116. 831742 | H20: Penangkapan | I20: Ikan laut | M20: Aktif | O20: =INDEX(desa!A:A,MATCH(B20,desa!B:B,0)) -> 4 | P20: PERIKANAN | Q20: =CONCATENATE("('",O20,";",C20,";",D20,";",E20,";",F20,";",G20,";",I20,";",M20,";",P20,"'),") -> ('4;KUB. Baci Lestari;Pemula;Madahu;10;-8. 528489, 116. 831742;Ikan laut;Aktif;PERIKANAN'),
A21: 18 | B21: Poto Tano | C21: KUB. Bahari Abadi | D21: Pemula | E21: Marzuki | F21: 10 | G21: -8. 528265, 116. 832133 | H21: Penangkapan | I21: Ikan laut | M21: Aktif | O21: =INDEX(desa!A:A,MATCH(B21,desa!B:B,0)) -> 4 | P21: PERIKANAN | Q21: =CONCATENATE("('",O21,";",C21,";",D21,";",E21,";",F21,";",G21,";",I21,";",M21,";",P21,"'),") -> ('4;KUB. Bahari Abadi;Pemula;Marzuki;10;-8. 528265, 116. 832133;Ikan laut;Aktif;PERIKANAN'),
A22: 19 | B22: Poto Tano | C22: KUB. Citra Bahari | D22: Pemula | E22: Mansaha | F22: 10 | G22: -8.529516, 116.831766 | H22: Penangkapan | I22: Ikan laut | M22: Aktif | O22: =INDEX(desa!A:A,MATCH(B22,desa!B:B,0)) -> 4 | P22: PERIKANAN | Q22: =CONCATENATE("('",O22,";",C22,";",D22,";",E22,";",F22,";",G22,";",I22,";",M22,";",P22,"'),") -> ('4;KUB. Citra Bahari;Pemula;Mansaha;10;-8.529516, 116.831766;Ikan laut;Aktif;PERIKANAN'),
A23: 20 | B23: Poto Tano | C23: KUB.Laut Biru | D23: Pemula | E23: Suharli | F23: 10 | G23: -8. 527658, 116. 832237 | H23: Penangkapan | I23: Ikan laut | M23: Aktif | O23: =INDEX(desa!A:A,MATCH(B23,desa!B:B,0)) -> 4 | P23: PERIKANAN | Q23: =CONCATENATE("('",O23,";",C23,";",D23,";",E23,";",F23,";",G23,";",I23,";",M23,";",P23,"'),") -> ('4;KUB.Laut Biru;Pemula;Suharli;10;-8. 527658, 116. 832237;Ikan laut;Aktif;PERIKANAN'),
A24: 21 | B24: Poto Tano | C24: KUB. Maju Indah | D24: Pemula | E24: Manaku | F24: 10 | G24: -8. 529558, 116. 832728 | H24: Penangkapan | I24: Ikan laut | M24: Aktif | O24: =INDEX(desa!A:A,MATCH(B24,desa!B:B,0)) -> 4 | P24: PERIKANAN | Q24: =CONCATENATE("('",O24,";",C24,";",D24,";",E24,";",F24,";",G24,";",I24,";",M24,";",P24,"'),") -> ('4;KUB. Maju Indah;Pemula;Manaku;10;-8. 529558, 116. 832728;Ikan laut;Aktif;PERIKANAN'),
A25: 22 | B25: Poto Tano | C25: KUB. Napoleon | D25: Pemula | E25: Agustino | F25: 10 | G25: -8. 527828, 116. 832348 | H25: Penangkapan | I25: Ikan laut | M25: Aktif | O25: =INDEX(desa!A:A,MATCH(B25,desa!B:B,0)) -> 4 | P25: PERIKANAN | Q25: =CONCATENATE("('",O25,";",C25,";",D25,";",E25,";",F25,";",G25,";",I25,";",M25,";",P25,"'),") -> ('4;KUB. Napoleon;Pemula;Agustino;10;-8. 527828, 116. 832348;Ikan laut;Aktif;PERIKANAN'),
A26: 23 | B26: Poto Tano | C26: KUB. Pembaharuan | D26: Pemula | E26: Sudirman | F26: 10 | G26: -8. 526633, 116. 831693 | H26: Penangkapan | I26: Ikan laut | M26: Aktif | O26: =INDEX(desa!A:A,MATCH(B26,desa!B:B,0)) -> 4 | P26: PERIKANAN | Q26: =CONCATENATE("('",O26,";",C26,";",D26,";",E26,";",F26,";",G26,";",I26,";",M26,";",P26,"'),") -> ('4;KUB. Pembaharuan;Pemula;Sudirman;10;-8. 526633, 116. 831693;Ikan laut;Aktif;PERIKANAN'),
A27: 24 | B27: Poto Tano | C27: KUB. Perubahan | D27: Pemula | E27: Manajai | F27: 10 | G27: -8.527303, 116. 831851 | H27: Penangkapan | I27: Ikan laut | M27: Aktif | O27: =INDEX(desa!A:A,MATCH(B27,desa!B:B,0)) -> 4 | P27: PERIKANAN | Q27: =CONCATENATE("('",O27,";",C27,";",D27,";",E27,";",F27,";",G27,";",I27,";",M27,";",P27,"'),") -> ('4;KUB. Perubahan;Pemula;Manajai;10;-8.527303, 116. 831851;Ikan laut;Aktif;PERIKANAN'),
A28: 25 | B28: Poto Tano | C28: KUB. Sikase – Ase | D28: Pemula | E28: Samarollah | F28: 10 | G28: -8.52883, 116. 832399 | H28: Penangkapan | I28: Ikan laut | M28: Aktif | O28: =INDEX(desa!A:A,MATCH(B28,desa!B:B,0)) -> 4 | P28: PERIKANAN | Q28: =CONCATENATE("('",O28,";",C28,";",D28,";",E28,";",F28,";",G28,";",I28,";",M28,";",P28,"'),") -> ('4;KUB. Sikase – Ase;Pemula;Samarollah;10;-8.52883, 116. 832399;Ikan laut;Aktif;PERIKANAN'),
A29: 26 | B29: Poto tano | C29: Tano Jaya | D29: Pemula | E29: Hadijah | F29: 10 | G29: -8.5277940, 116.832145 | H29: pengolah | I29: Abon Ikan | M29: Aktif | O29: =INDEX(desa!A:A,MATCH(B29,desa!B:B,0)) -> 4 | P29: PERIKANAN | Q29: =CONCATENATE("('",O29,";",C29,";",D29,";",E29,";",F29,";",G29,";",I29,";",M29,";",P29,"'),") -> ('4;Tano Jaya;Pemula;Hadijah;10;-8.5277940, 116.832145;Abon Ikan;Aktif;PERIKANAN'),
A30: 27 | B30: Poto Tano | C30: KUB Pelita Poto Tano | D30: Pemula | E30: Mahari | F30: 15 | G30: - | H30: Penangkapan | I30: Ikan Laut | J30: - | K30: - | L30: - | M30: Aktif | O30: =INDEX(desa!A:A,MATCH(B30,desa!B:B,0)) -> 4 | P30: PERIKANAN | Q30: =CONCATENATE("('",O30,";",C30,";",D30,";",E30,";",F30,";",G30,";",I30,";",M30,";",P30,"'),") -> ('4;KUB Pelita Poto Tano;Pemula;Mahari;15;-;Ikan Laut;Aktif;PERIKANAN'),
A31: 28 | B31: Poto Tano | C31: KUB Jaring Maero | D31: Pemula | E31: Mustar | F31: 17 | G31: - | H31: Penangkapan | I31: Ikan Laut | J31: - | K31: - | L31: - | M31: Aktif | O31: =INDEX(desa!A:A,MATCH(B31,desa!B:B,0)) -> 4 | P31: PERIKANAN | Q31: =CONCATENATE("('",O31,";",C31,";",D31,";",E31,";",F31,";",G31,";",I31,";",M31,";",P31,"'),") -> ('4;KUB Jaring Maero;Pemula;Mustar;17;-;Ikan Laut;Aktif;PERIKANAN'),
A32: 29 | B32: Poto Tano | C32: Poklahsar Persatuan Pasir Putih | D32: Pemula | E32: Yuliana | F32: 10 | G32: - | H32: Pengolahan | I32: Ikan Laut | J32: - | K32: - | L32: - | M32: Aktif | O32: =INDEX(desa!A:A,MATCH(B32,desa!B:B,0)) -> 4 | P32: PERIKANAN | Q32: =CONCATENATE("('",O32,";",C32,";",D32,";",E32,";",F32,";",G32,";",I32,";",M32,";",P32,"'),") -> ('4;Poklahsar Persatuan Pasir Putih;Pemula;Yuliana;10;-;Ikan Laut;Aktif;PERIKANAN'),
A33: 30 | B33: Tambak sari | C33: Pemuda Perubahan | D33: Pemula | E33: Saepul Haq | F33: 10 | G33: -8.564049, 116.842005 | H33: Pembesaran | I33: Nila | J33: kolam terpal | K33: Semi Intensif | L33: 131 | M33: Aktif | O33: =INDEX(desa!A:A,MATCH(B33,desa!B:B,0)) -> 6 | P33: PERIKANAN | Q33: =CONCATENATE("('",O33,";",C33,";",D33,";",E33,";",F33,";",G33,";",I33,";",M33,";",P33,"'),") -> ('6;Pemuda Perubahan;Pemula;Saepul Haq;10;-8.564049, 116.842005;Nila;Aktif;PERIKANAN'),
A34: 31 | B34: Tambak sari | C34: KUB Plasma | D34: Pemula | E34: Margana | F34: 10 | G34: -8.567836, 118.842697 | H34: Penangkapan | I34: Ikan Laut | M34: Aktif | O34: =INDEX(desa!A:A,MATCH(B34,desa!B:B,0)) -> 6 | P34: PERIKANAN | Q34: =CONCATENATE("('",O34,";",C34,";",D34,";",E34,";",F34,";",G34,";",I34,";",M34,";",P34,"'),") -> ('6;KUB Plasma;Pemula;Margana;10;-8.567836, 118.842697;Ikan Laut;Aktif;PERIKANAN'),
A35: 32 | B35: Kokarlian | C35: Pokdakan Sekar Bahari | D35: Madya | E35: Ibnul Irsal | F35: 10 | G35: -8.538898, 116.856802 | H35: Pembesaran | I35: Rumput Laut | K35: Long Line | L35: 5000 | M35: Aktif | O35: =INDEX(desa!A:A,MATCH(B35,desa!B:B,0)) -> 2 | P35: PERIKANAN | Q35: =CONCATENATE("('",O35,";",C35,";",D35,";",E35,";",F35,";",G35,";",I35,";",M35,";",P35,"'),") -> ('2;Pokdakan Sekar Bahari;Madya;Ibnul Irsal;10;-8.538898, 116.856802;Rumput Laut;Aktif;PERIKANAN'),
A36: 33 | B36: Kokarlian | C36: Pokdakan Samudera | D36: Madya | E36: Muhammad Rojik | F36: 10 | G36: -8.538903, 116.856037 | H36: Pembesaran | I36: Rumput Laut | K36: Long Line | L36: 5000 | M36: Aktif | O36: =INDEX(desa!A:A,MATCH(B36,desa!B:B,0)) -> 2 | P36: PERIKANAN | Q36: =CONCATENATE("('",O36,";",C36,";",D36,";",E36,";",F36,";",G36,";",I36,";",M36,";",P36,"'),") -> ('2;Pokdakan Samudera;Madya;Muhammad Rojik;10;-8.538903, 116.856037;Rumput Laut;Aktif;PERIKANAN'),
A37: 34 | B37: Tebo | C37: Penyare | D37: Pemula | E37: Syarifuddin | F37: 9 | G37: -8.608167, 116.860619 | H37: Pembesaran | I37: Nila, karper | J37: kolam tanah, kolam beton | K37: Tradisional | L37: 1185 | M37: Aktif | O37: =INDEX(desa!A:A,MATCH(B37,desa!B:B,0)) -> 7 | P37: PERIKANAN | Q37: =CONCATENATE("('",O37,";",C37,";",D37,";",E37,";",F37,";",G37,";",I37,";",M37,";",P37,"'),") -> ('7;Penyare;Pemula;Syarifuddin;9;-8.608167, 116.860619;Nila, karper;Aktif;PERIKANAN'),
A38: 35 | B38: Tua nanga | C38: Pokdakan Bangka Bella | D38: Pemula | E38: Samsuddin | F38: 11 | G38: - | H38: Pembesaran | I38: Rumput Laut | K38: Patok dasar | L38: 6.6 | M38: Aktif | O38: =INDEX(desa!A:A,MATCH(B38,desa!B:B,0)) -> 8 | P38: PERIKANAN | Q38: =CONCATENATE("('",O38,";",C38,";",D38,";",E38,";",F38,";",G38,";",I38,";",M38,";",P38,"'),") -> ('8;Pokdakan Bangka Bella;Pemula;Samsuddin;11;-;Rumput Laut;Aktif;PERIKANAN'),
A39: 36 | B39: Tua nanga | C39: Pokdakan Bukit Kenangan | D39: Pemula | E39: Muhatadim | F39: 11 | G39: -- | H39: Pembesaran | I39: Rumput Laut | K39: Patok dasar | L39: 6.6 | M39: Aktif | O39: =INDEX(desa!A:A,MATCH(B39,desa!B:B,0)) -> 8 | P39: PERIKANAN | Q39: =CONCATENATE("('",O39,";",C39,";",D39,";",E39,";",F39,";",G39,";",I39,";",M39,";",P39,"'),") -> ('8;Pokdakan Bukit Kenangan;Pemula;Muhatadim;11;--;Rumput Laut;Aktif;PERIKANAN'),
A40: 37 | B40: Tua nanga | C40: Pokdakan Maju Jaya | D40: Pemula | E40: Jayadi | F40: 11 | G40: - | H40: Pembesaran | I40: Rumput Laut | K40: Patok dasar | L40: 6.6 | M40: Aktif | O40: =INDEX(desa!A:A,MATCH(B40,desa!B:B,0)) -> 8 | P40: PERIKANAN | Q40: =CONCATENATE("('",O40,";",C40,";",D40,";",E40,";",F40,";",G40,";",I40,";",M40,";",P40,"'),") -> ('8;Pokdakan Maju Jaya;Pemula;Jayadi;11;-;Rumput Laut;Aktif;PERIKANAN'),
A41: 38 | B41: Tua nanga | C41: Pokdakan Niat Balong | D41: Pemula | E41: Syafruddin | F41: 10 | G41: - | H41: Pembesaran | I41: Rumput Laut | K41: Patok dasar | L41: 6.6 | M41: Aktif | O41: =INDEX(desa!A:A,MATCH(B41,desa!B:B,0)) -> 8 | P41: PERIKANAN | Q41: =CONCATENATE("('",O41,";",C41,";",D41,";",E41,";",F41,";",G41,";",I41,";",M41,";",P41,"'),") -> ('8;Pokdakan Niat Balong;Pemula;Syafruddin;10;-;Rumput Laut;Aktif;PERIKANAN'),
...

Sheet Sheet1
A1: Penjelasan Tiap Istilah
A3: 1. 🎣 Kelompok Nelayan
O4: 1 | P4: data legalitas bumdes apa aja
A5: Kumpulan nelayan tangkap (melaut) | O5: 2 | P5: informasi umum klembagaan
A6: Fokus: menangkap ikan di laut
A10: 2. 🐟 Pokdakan (Kelompok Pembudidaya Ikan)
A12: Kelompok yang membudidayakan ikan
A13: Contoh:
A14: Tambak ikan
A15: Keramba
A16: Kolam budidaya
A18: 👉 Bukan nelayan tangkap, tapi petani ikan
A22: 3. 🐠 Poklahsar (Kelompok Pengolah dan Pemasar)
A24: Kelompok yang mengolah dan menjual hasil perikanan
A25: Contoh:
A26: Ikan asin
... A52: Melaporkan pelanggaran

Sheet desa
A1: 1 | B1: Kiantar | C1: 6
A2: 2 | B2: Kokarlian | C2: 6
A3: 3 | B3: Mantar | C3: 6
A4: 4 | B4: Poto Tano | C4: 6
A5: 5 | B5: Senayan | C5: 6
A6: 6 | B6: Tambak Sari | C6: 6
A7: 7 | B7: Tebo | C7: 6
A8: 8 | B8: Tuananga | C8: 6
A9: 8 | B9: Tua nanga | C9: 6
A10: 6 | B10: upt Tambak Sari | C10: 6
